Workbook

Sheet 통계
A1: 온라인사업부 | B1: 46174 | D1: 46181 | F1: 46188 | H1: 46195 | J1: 46196
B2: 수량 | C2: 금액 | D2: 수량 | E2: 금액 | F2: 수량 | G2: 금액 | H2: 수량 | I2: 금액 | J2: 수량 | K2: 금액
A3: 굿스마일 | B3: 19590 | C3: 341132001 | D3: 15257 | E3: 351711266 | F3: 13965 | G3: 388363419 | H3: =굿스마일!D1242 | I3: =굿스마일!E1242 | J3: ='굿스마일'!D1589 | K3: ='굿스마일'!E1589
A4: 메가하우스 | B4: 1811 | C4: 37660543 | D4: 1758 | E4: 48925767 | F4: 1695 | G4: 47241286 | H4: =메가하우스!D138 | I4: =메가하우스!E138 | J4: ='메가하우스'!D214 | K4: ='메가하우스'!E214
A5: 부시로드 | B5: 14834 | C5: 38271721 | D5: 14680 | E5: 37840685 | F5: 14549 | G5: 37258240 | H5: =부시로드!D1004 | I5: =부시로드!E1004 | J5: ='부시로드'!D1056 | K5: ='부시로드'!E1056
A6: 블로키 | B6: 91 | C6: 3879500 | D6: 89 | E6: 3816000 | F6: 89 | G6: 3816000 | H6: ='블로키 '!D31 | I6: ='블로키 '!E31 | J6: ='블로키 '!D31 | K6: ='블로키 '!E31
A7: 반다이남코 | B7: 437 | C7: 1635451 | D7: 436 | E7: 1629711 | F7: 507 | G7: 3927591 | H7: =반다이남코!D121 | I7: =반다이남코!E121 | J7: ='반다이남코'!D129 | K7: ='반다이남코'!E129
A8: 핫토이 | B8: 125 | C8: 10967400 | D8: 125 | E8: 10967400 | F8: 124 | G8: 10953400 | H8: =핫토이_온라인!D55 | I8: =핫토이_온라인!E55 | J8: ='핫토이_온라인'!D67 | K8: ='핫토이_온라인'!E67
A9: 하비재팬 | B9: 279 | C9: 33286061 | D9: 279 | E9: 33286061 | F9: 276 | G9: 33095852 | H9: =하비재팬!D11 | I9: =하비재팬!E11 | J9: ='하비재팬'!D14 | K9: ='하비재팬'!E14
A10: CCS TOYS | B10: 213 | C10: 52600772 | D10: 1054 | E10: 51516220 | F10: 1030 | G10: 48262564 | H10: ='CCS '!D8 | I10: ='CCS '!E8 | J10: ='CCS '!D8 | K10: ='CCS '!E8
A11: P001 | B11: 533 | D11: 533 | F11: 533 | H11: ='P001 온라인'!D2 | J11: ='P001 온라인'!D2
A12: 코코파스튜디오 | B12: 24 | C12: 2208768 | D12: 21 | E12: 1932672 | F12: 21 | G12: 1932672 | H12: =코코파!D2 | I12: =코코파!E2 | J12: ='코코파'!D5 | K12: ='코코파'!E5
A13: 기타브랜드 | B13: 1143 | C13: 18468300 | D13: 1143 | E13: 18468300 | F13: 1136 | G13: 18373800 | H13: =기타브랜드!D142 | I13: =기타브랜드!E142 | J13: ='기타브랜드'!D187 | K13: ='기타브랜드'!E187
A14: 합 계 | B14: 39080 | C14: 540110517 | D14: 35375 | E14: 560094082 | F14: 33925 | G14: 593224824 | H14: =SUM(H3:H13) | I14: =SUM(I3:I13) | J14: =SUM(H3:H13) | K14: =SUM(I3:I13)
A16: 영업사업부 | B16: 46174 | D16: 46181 | F16: 46188 | H16: 46195
B17: 수량 | C17: 금액 | D17: 수량 | E17: 금액 | F17: 수량 | G17: 금액 | H17: 수량 | I17: 금액
A18: 굿스마일 | B18: 23493 | C18: 232726133 | D18: 23148 | E18: 260325940 | F18: 13356 | G18: 184787176 | H18: =굿스마일!F1242 | I18: =굿스마일!G1242 | J18: ='굿스마일'!F1589 | K18: ='굿스마일'!G1589
A19: 메가하우스 | B19: 446 | C19: 4908247 | D19: 1618 | E19: 11826035 | F19: 1439 | G19: 10997853 | H19: =메가하우스!F138 | I19: =메가하우스!G138 | J19: ='메가하우스'!F214 | K19: ='메가하우스'!G214
A20: 부시로드 | B20: 11200 | C20: 18358602 | D20: 11103 | E20: 18259060 | F20: 10147 | G20: 16230694 | H20: =부시로드!F1004 | I20: =부시로드!G1004 | J20: ='부시로드'!F1056 | K20: ='부시로드'!G1056
A21: 블로키 | B21: 70 | C21: 3197000 | D21: 93 | E21: 5155500 | F21: 209 | G21: 10921000 | H21: ='블로키 '!F31 | I21: ='블로키 '!G31 | J21: ='블로키 '!F31 | K21: ='블로키 '!G31
A22: 반다이남코 | B22: 1890 | C22: 20724179 | D22: 1851 | E22: 19805463 | F22: 1981 | G22: 25917054 | H22: =반다이남코!F121 | I22: =반다이남코!G121 | J22: ='반다이남코'!F129 | K22: ='반다이남코'!G129
A23: 하비재팬 | B23: 0 | C23: 0 | D23: 0 | E23: 0 | F23: 0 | G23: 0 | H23: 0 | I23: 0
A24: CCS TOYS | B24: 0 | C24: 0 | D24: 107 | E24: 0 | F24: 0 | G24: 0 | H24: 0 | I24: 0
A25: 코코파스튜디오 | B25: 0 | C25: 0 | D25: 0 | E25: 0 | F25: 0 | G25: 0 | H25: 0 | I25: 0
A26: 기타브랜드 | B26: 1091 | C26: 7360140 | D26: 1196 | E26: 8761390 | F26: 1158 | G26: 8374290 | H26: =기타브랜드!F142 | I26: =기타브랜드!G142 | J26: ='기타브랜드'!F187 | K26: ='기타브랜드'!G187
A27: 합 계 | B27: 38190 | C27: 287274301 | D27: 39116 | E27: 324133388 | F27: 28290 | G27: 257228067 | H27: =SUM(H18:H26) | I27: =SUM(I18:I26) | J27: =SUM(H18:H26) | K27: =SUM(I18:I26)
A29: 영업사업부_위탁매장 | B29: 46174 | D29: 46181 | F29: 46188 | H29: 46195
B30: 수량 | C30: 금액 | D30: 수량 | E30: 금액 | F30: 수량 | G30: 금액 | H30: 수량 | I30: 금액
A31: 굿스마일 | F31: 9106 | G31: 115169825 | H31: =굿스마일!H1242 | I31: =굿스마일!I1242 | J31: ='굿스마일'!H1589 | K31: ='굿스마일'!I1589
A32: 메가하우스 | F32: 0 | G32: 0 | H32: 0 | I32: 0
A33: 부시로드 | F33: 902 | G33: 1968492 | H33: =부시로드!H1004 | I33: =부시로드!I1004 | J33: ='부시로드'!H1056 | K33: ='부시로드'!I1056
A34: 합 계 | F34: 10008 | G34: 117138317 | H34: =SUM(H31:H33) | I34: =SUM(I31:I33) | J34: =SUM(H31:H33) | K34: =SUM(I31:I33)
A36: 사업지원 TF | B36: 46174 | D36: 46181 | F36: 46188 | H36: 46195
B37: 수량 | C37: 금액 | D37: 수량 | E37: 금액 | F37: 수량 | G37: 금액 | H37: 수량 | I37: 금액
A38: 굿스마일 | B38: 3344 | C38: 15819414 | D38: 3344 | E38: 18280134 | F38: 3344 | G38: 25461198 | H38: =굿스마일!J1242 | I38: =굿스마일!K1242 | J38: ='굿스마일'!J1589 | K38: ='굿스마일'!K1589
A39: 메가하우스 | B39: 2 | C39: 0 | D39: 4 | E39: 0 | F39: 4 | G39: 0 | H39: =메가하우스!H138 | I39: 0 | J39: ='메가하우스'!H214
A40: 부시로드 | B40: 828 | C40: 973440 | D40: 828 | E40: 973440 | F40: 828 | G40: 973440 | H40: =부시로드!J1004 | I40: =부시로드!K1004 | J40: ='부시로드'!J1056 | K40: ='부시로드'!K1056
A41: 합 계 | B41: 4174 | C41: 16792854 | D41: 4176 | E41: 19253574 | F41: 4176 | G41: 26434638 | H41: =SUM(H38:H40) | I41: =SUM(I38:I40) | J41: =SUM(H38:H40) | K41: =SUM(I38:I40)
A43: 컨텐츠기획부 | B43: 46174 | D43: 46181 | F43: 46188 | H43: 46195
B44: 수량 | C44: 금액 | D44: 수량 | E44: 금액 | F44: 수량 | G44: 금액 | H44: 수량 | I44: 금액
...

Sheet 굿스마일
A1: 브랜드 | B1: 품목명 | C1: 입고단가 | D1: 온라인 수량 | E1: 온라인 재고금액 | F1: 영업 수량 | G1: 영업 재고금액 | H1: 영업_위탁매장 수량 | I1: 영업_위탁매장 재고금액 | J1: 사업지원 수량 | K1: 사업지원 재고금액
A2: 굿스마일 | B2: [굿스마일] 【Rerelease】 Chozokado CRAZY DIAMOND | D2: 10 | E2: =D2*C2 | F2: 2 | G2: =F2*C2 | H2: 0 | I2: =H2*C2 | J2: 0 | K2: =J2*C2
A3: 굿스마일 | B3: [굿스마일] 【Rerelease】 Chozokado Josuke Higashikata | D3: 0 | E3: =D3*C3 | F3: 12 | G3: =F3*C3 | H3: 0 | I3: =H3*C3 | J3: 0 | K3: =J3*C3
A4: 굿스마일 | B4: [굿스마일] 【Rerelease】 figma Akaza | D4: 16 | E4: =D4*C4 | F4: 44 | G4: =F4*C4 | H4: 0 | I4: =H4*C4 | J4: 0 | K4: =J4*C4
A5: 굿스마일 | B5: [굿스마일] 【Rerelease】 figma Saber/Miyamoto Musashi | D5: 16 | E5: =D5*C5 | F5: 20 | G5: =F5*C5 | H5: 0 | I5: =H5*C5 | J5: 0 | K5: =J5*C5
A6: 굿스마일 | B6: [굿스마일] 【Rerelease】 figma Scarlet | D6: 51 | E6: =D6*C6 | F6: 57 | G6: =F6*C6 | H6: 0 | I6: =H6*C6 | J6: 0 | K6: =J6*C6
A7: 굿스마일 | B7: [굿스마일] 【Rerelease】 hololive production Hikkake Figure -Inugami Korone- | D7: 9 | E7: =D7*C7 | F7: 21 | G7: =F7*C7 | H7: 0 | I7: =H7*C7 | J7: 0 | K7: =J7*C7
A8: 굿스마일 | B8: [굿스마일] 【Rerelease】 hololive production Hikkake Figure -Nekomata Okayu- | D8: 9 | E8: =D8*C8 | F8: 21 | G8: =F8*C8 | H8: 0 | I8: =H8*C8 | J8: 0 | K8: =J8*C8
A9: 굿스마일 | B9: [굿스마일] 【Rerelease】 hololive production Hikkake Figure -Robocosan- | D9: 18 | E9: =D9*C9 | F9: 12 | G9: =F9*C9 | H9: 0 | I9: =H9*C9 | J9: 0 | K9: =J9*C9
A10: 굿스마일 | B10: [굿스마일] 【Rerelease】 Makima: Bunny Ver. | D10: 12 | E10: =D10*C10 | F10: 12 | G10: =F10*C10 | H10: 0 | I10: =H10*C10 | J10: 0 | K10: =J10*C10
A11: 굿스마일 | B11: [굿스마일] 【Rerelease】 Mirko | D11: 4 | E11: =D11*C11 | F11: 0 | G11: =F11*C11 | H11: 0 | I11: =H11*C11 | J11: 0 | K11: =J11*C11
A12: 굿스마일 | B12: [굿스마일] 【Rerelease】 MODEROID ED-209 | D12: 28 | E12: =D12*C12 | F12: 32 | G12: =F12*C12 | H12: 0 | I12: =H12*C12 | J12: 0 | K12: =J12*C12
A13: 굿스마일 | B13: [굿스마일] 【Rerelease】 MODEROID RoboCop | D13: 6 | E13: =D13*C13 | F13: 42 | G13: =F13*C13 | H13: 0 | I13: =H13*C13 | J13: 0 | K13: =J13*C13
... A74: 굿스마일 | B74: [굿스마일] Ume Hanami: Bunny Ver. | D74: 3 | E74: =D74*C74 | F74: 1 | G74: =F74*C74 | H74: 0 | I74: =H74*C74 | J74: 0 | K74: =J74*C74
A75: 굿스마일 | B75: [굿스마일](Rerelease) GUILTY GEAR STRIVE Plushie Jack O | C75: 31934 | D75: 2 | E75: =D75*C75 | F75: 0 | G75: =F75*C75 | H75: 0 | I75: =H75*C75 | J75: 0 | K75: =J75*C75
A76: 굿스마일 | B76: [굿스마일](Rerelease) Kuripan Plushie Karin Asaka | D76: 2 | E76: =D76*C76 | F76: 0 | G76: =F76*C76 | H76: 0 | I76: =H76*C76 | J76: 0 | K76: =J76*C76
A77: 굿스마일 | B77: [굿스마일](Rerelease) Lycoris Recoil Plushie Takina Inoue: Café LycoReco Ver. | C77: 25430 | D77: 2 | E77: =D77*C77 | F77: 0 | G77: =F77*C77 | H77: 2 | I77: =H77*C77 | J77: 0 | K77: =J77*C77
A78: 굿스마일 | B78: [굿스마일](Rerelease) Plushie Chisato Nishikigi | C78: 25430 | D78: 0 | E78: =D78*C78 | F78: 0 | G78: =F78*C78 | H78: 1 | I78: =H78*C78 | J78: 0 | K78: =J78*C78
A79: 굿스마일 | B79: [굿스마일](Rerelease) Plushie Chisato Nishikigi: Café LycoReco Ver. | C79: 25430 | D79: 2 | E79: =D79*C79 | F79: 0 | G79: =F79*C79 | H79: 3 | I79: =H79*C79 | J79: 0 | K79: =J79*C79
A80: 굿스마일 | B80: [굿스마일](Rerelease) Plushie Heather Mason | C80: 22252 | D80: 3 | E80: =D80*C80 | F80: 0 | G80: =F80*C80 | H80: 0 | I80: =H80*C80 | J80: 0 | K80: =J80*C80
A81: 굿스마일 | B81: [굿스마일](Rerelease) Plushie Red Pyramid Thing | C81: 22252 | D81: 3 | E81: =D81*C81 | F81: 0 | G81: =F81*C81 | H81: 0 | I81: =H81*C81 | J81: 0 | K81: =J81*C81
A82: 굿스마일 | B82: [굿스마일](Rerelease) Plushie Robbie the Rabbit | C82: 22252 | D82: 3 | E82: =D82*C82 | F82: 0 | G82: =F82*C82 | H82: 0 | I82: =H82*C82 | J82: 0 | K82: =J82*C82
A83: 굿스마일 | B83: [굿스마일][B]Nendoroid Rihito Sajo & Hikaru Kusakabe | D83: 0 | E83: =D83*C83 | F83: 1 | G83: =F83*C83 | H83: 0 | I83: =H83*C83 | J83: 0 | K83: =J83*C83
A84: 굿스마일 | B84: [굿스마일][BUZZmod.] Cyberpunk: Edgerunners LUCY | D84: 2 | E84: =D84*C84 | F84: 0 | G84: =F84*C84 | H84: 0 | I84: =H84*C84 | J84: 0 | K84: =J84*C84
A85: 굿스마일 | B85: [굿스마일][Dance Dance Dance] Kaede Takagaki + | D85: 1 | E85: =D85*C85 | F85: 0 | G85: =F85*C85 | H85: 0 | I85: =H85*C85 | J85: 0 | K85: =J85*C85
A86: 굿스마일 | B86: [굿스마일]【Re-pro Model】 Capcom Figure Builder Creators Model Mizutsune | C86: 118405 | D86: 1 | E86: =D86*C86 | F86: 0 | G86: =F86*C86 | H86: 0 | I86: =H86*C86 | J86: 0 | K86: =J86*C86
A87: 굿스마일 | B87: [굿스마일]【Rerelease】 Asuka Shikinami Langley Plugsuit Ver. New Movie Edition | C87: 103633 | D87: 0 | E87: =D87*C87 | F87: 0 | G87: =F87*C87 | H87: 1 | I87: =H87*C87 | J87: 0 | K87: =J87*C87
A88: 굿스마일 | B88: [굿스마일]【Rerelease】 Chiaki Nanami | C88: 132284 | D88: 1 | E88: =D88*C88 | F88: 0 | G88: =F88*C88 | H88: 0 | I88: =H88*C88 | J88: 0 | K88: =J88*C88
A89: 굿스마일 | B89: [굿스마일]【Rerelease】 figma Alice | D89: 10 | E89: =D89*C89 | F89: 0 | G89: =F89*C89 | H89: 0 | I89: =H89*C89 | J89: 0 | K89: =J89*C89
A90: 굿스마일 | B90: [굿스마일]【Rerelease】 figma Rikka Takarada | C90: 66755 | D90: 3 | E90: =D90*C90 | F90: 0 | G90: =F90*C90 | H90: 0 | I90: =H90*C90 | J90: 0 | K90: =J90*C90
A91: 굿스마일 | B91: [굿스마일]【Rerelease】 figma Sophia F. Shirring: Bikini Armor ver. | D91: 13 | E91: =D91*C91 | F91: 0 | G91: =F91*C91 | H91: 0 | I91: =H91*C91 | J91: 0 | K91: =J91*C91
A92: 굿스마일 | B92: [굿스마일]【Rerelease】 figma Splatoon Boy: DX Edition | C92: 110783 | D92: 9 | E92: =D92*C92 | F92: 0 | G92: =F92*C92 | H92: 0 | I92: =H92*C92 | J92: 0 | K92: =J92*C92
A93: 굿스마일 | B93: [굿스마일]【Rerelease】 figma Splatoon Girl: DX Edition | C93: 113271 | D93: 52 | E93: =D93*C93 | F93: 0 | G93: =F93*C93 | H93: 0 | I93: =H93*C93 | J93: 0 | K93: =J93*C93
A94: 굿스마일 | B94: [굿스마일]【Rerelease】 FT-00004A Azuma | C94: 36086 | D94: 6 | E94: =D94*C94 | F94: 0 | G94: =F94*C94 | H94: 0 | I94: =H94*C94 | J94: 0 | K94: =J94*C94
A95: 굿스마일 | B95: [굿스마일]【Rerelease】 FT-00004A Azuma [2P COLOR VER.] | C95: 36086 | D95: 6 | E95: =D95*C95 | F95: 0 | G95: =F95*C95 | H95: 0 | I95: =H95*C95 | J95: 0 | K95: =J95*C95
A96: 굿스마일 | B96: [굿스마일]【Rerelease】 GUILTY GEAR -STRIVE- Plushie Ramlethal Valentine | C96: 31934 | D96: 0 | E96: =D96*C96 | F96: 2 | G96: =F96*C96 | H96: 0 | I96: =H96*C96 | J96: 0 | K96: =J96*C96
A97: 굿스마일 | B97: [굿스마일]【Rerelease】 Hayate HIsakawa[O-Ku-Ri-Mo-No Sunday ! ]+ | C97: 169083 | D97: 4 | E97: =D97*C97 | F97: 0 | G97: =F97*C97 | H97: 0 | I97: =H97*C97 | J97: 0 | K97: =J97*C97
A98: 굿스마일 | B98: [굿스마일]【Rerelease】 MODEROID ARHAN | D98: 0 | E98: =D98*C98 | F98: 1 | G98: =F98*C98 | H98: 0 | I98: =H98*C98 | J98: 0 | K98: =J98*C98
A99: 굿스마일 | B99: [굿스마일]【Rerelease】 MODEROID Black Sarena | C99: 60734 | D99: 5 | E99: =D99*C99 | F99: 0 | G99: =F99*C99 | H99: 0 | I99: =H99*C99 | J99: 0 | K99: =J99*C99
A100: 굿스마일 | B100: [굿스마일]【Rerelease】 MODEROID Dynazenon | C100: 47521 | D100: 12 | E100: =D100*C100 | F100: 0 | G100: =F100*C100 | H100: 0 | I100: =H100*C100 | J100: 0 | K100: =J100*C100
...

Sheet 메가하우스
A1: 브랜드 | B1: 품목명 | C1: 입고단가 | D1: 온라인 수량 | E1: 온라인 재고금액 | F1: 영업 수량 | G1: 영업 재고금액 | H1: 사업지원 수량 | I1: 사업지원 재고금액
A2: 메가하우스 | B2: [메가하우스]Acrylic Stand Gintama Prince Hata & Animal Paradise | C2: 5116 | D2: 36 | E2: =D2*C2 | F2: 0 | G2: =F2*C2 | H2: 0 | I2: =H2*C2
A3: 메가하우스 | B3: [메가하우스]Acrylic Stand Gintama Prince Hata & Animal Paradise Farm of Love & Peace | C3: 5199 | D3: 30 | E3: =D3*C3 | F3: 132 | G3: =F3*C3 | H3: 0 | I3: =H3*C3
A4: 메가하우스 | B4: [메가하우스]Chara Catcher～ Gnosia vol.1 | D4: 16 | E4: =D4*C4 | F4: 32 | G4: =F4*C4 | H4: 0 | I4: =H4*C4
A5: 메가하우스 | B5: [메가하우스]Chara Catcher～ Gnosia vol.2 | C5: 5540 | D5: 0 | E5: =D5*C5 | F5: 32 | G5: =F5*C5 | H5: 0 | I5: =H5*C5
A6: 메가하우스 | B6: [메가하우스]Charm Patisserie Kirbys Dream Land Kirbys cookie time（Repeat） | C6: 4194 | D6: 5 | E6: =D6*C6 | F6: 6 | G6: =F6*C6 | H6: 0 | I6: =H6*C6
A7: 메가하우스 | B7: [메가하우스]Chokorin Collection Mobile Suit Gundam GQuuuuuuX | C7: 5798 | D7: 48 | E7: =D7*C7 | F7: 0 | G7: =F7*C7 | H7: 0 | I7: =H7*C7
A8: 메가하우스 | B8: [메가하우스]Chokorin Collection Mr. Ginpachis Zany Class Vol.2 | C8: 5891 | D8: 138 | E8: =D8*C8 | F8: 840 | G8: =F8*C8 | H8: 0 | I8: =H8*C8
A9: 메가하우스 | B9: [메가하우스]Chokorin Mascot Gintama（Repeat） | C9: 5344 | D9: 6 | E9: =D9*C9 | F9: 0 | G9: =F9*C9 | H9: 0 | I9: =H9*C9
A10: 메가하우스 | B10: [메가하우스]Cosmo Fleet SP STAR BLAZERS 2202 U.N.C.F. Andromeda Class 1st Battleship Andromeda（Repeat） | C10: 63305 | D10: 2 | E10: =D10*C10 | F10: 0 | G10: =F10*C10 | H10: 0 | I10: =H10*C10
A11: 메가하우스 | B11: [메가하우스]Cosmo Fleet Special MOBILE SUIT GUNDAM THE ORIGIN Musai kai-class Valkyrie Re. | C11: 60745 | D11: 6 | E11: =D11*C11 | F11: 0 | G11: =F11*C11 | H11: 0 | I11: =H11*C11
A12: 메가하우스 | B12: [메가하우스]DESKTOP ARMY Princess Connect! Re:Dive | C12: 18763 | D12: 5 | E12: =D12*C12 | F12: 0 | G12: =F12*C12 | H12: 0 | I12: =H12*C12
A13: 메가하우스 | B13: [메가하우스]Digimon Adventure Digicolle! MIX （Repeat） | D13: 90 | E13: =D13*C13 | F13: 0 | G13: =F13*C13 | H13: 0 | I13: =H13*C13
A14: 메가하우스 | B14: [메가하우스]FIGURE JUJUTSUKAISEN Satoru Gojo ・ Suguru Geto KOSEN ver. set 【with gift】 | C14: 278831 | D14: 1 | E14: =D14*C14 | F14: 0 | G14: =F14*C14 | H14: 0 | I14: =H14*C14
A15: 메가하우스 | B15: [메가하우스]FIRE SUPERION G.T.R | D15: 1 | E15: =D15*C15 | F15: 0 | G15: =F15*C15 | H15: 0 | I15: =H15*C15
A16: 메가하우스 | B16: [메가하우스]G.E.M. Series 3-Z Ginpachi Sensei Ginpachi Sakata Reiwa Ver. | C16: 125813 | D16: 44 | E16: =D16*C16 | F16: 0 | G16: =F16*C16 | H16: 0 | I16: =H16*C16
A17: 메가하우스 | B17: [메가하우스]G.E.M. series Birth of Kitaro The Mystery of GeGeGe Palm Size Kitaros dad | C17: 53074 | D17: 61 | E17: =D17*C17 | F17: 0 | G17: =F17*C17 | H17: 0 | I17: =H17*C17
A18: 메가하우스 | B18: [메가하우스]G.E.M. series Demon Slayer： Kimetsu no Yaiba Upper Rank 3 Akaza（Repeat） | D18: 8 | E18: =D18*C18 | F18: 0 | G18: =F18*C18 | H18: 0 | I18: =H18*C18
A19: 메가하우스 | B19: [메가하우스]G.E.M. series Gintama Palm Size Gin san | C19: 50848 | D19: 108 | E19: =D19*C19 | F19: 10 | G19: =F19*C19 | H19: 0 | I19: =H19*C19
A20: 메가하우스 | B20: [메가하우스]G.E.M. series Gintama Palm Size Hijikata san | C20: 50910 | D20: 108 | E20: =D20*C20 | F20: 8 | G20: =F20*C20 | H20: 0 | I20: =H20*C20
A21: 메가하우스 | B21: [메가하우스]G.E.M. Series Haikyu！！ Palm size Shoyo Hinata second uniform Ver. | D21: 1 | E21: =D21*C21 | F21: 0 | G21: =F21*C21 | H21: 0 | I21: =H21*C21
A22: 메가하우스 | B22: [메가하우스]G.E.M. series Haikyu！！ Palm size Tobio Kageyama（Repeat） | C22: 48718 | D22: 1 | E22: =D22*C22 | F22: 0 | G22: =F22*C22 | H22: 0 | I22: =H22*C22
A23: 메가하우스 | B23: [메가하우스]G.M.G. COLLECTION 01 Mobile Suit Gundam Earth Federation Amuro Ray | C23: 21631 | D23: 1 | E23: =D23*C23 | F23: 0 | G23: =F23*C23 | H23: 0 | I23: =H23*C23
A24: 메가하우스 | B24: [메가하우스]G.M.G. COLLECTION 02 Principality of Zeon Char Aznable | C24: 21631 | D24: 1 | E24: =D24*C24 | F24: 0 | G24: =F24*C24 | H24: 0 | I24: =H24*C24
A25: 메가하우스 | B25: [메가하우스]G.M.G. COLLECTION 03 Principality of Zeon Ramba Ral | C25: 21631 | D25: 1 | E25: =D25*C25 | F25: 0 | G25: =F25*C25 | H25: 0 | I25: =H25*C25
A26: 메가하우스 | B26: [메가하우스]G.M.G. COLLECTION 04 Mobile Suit Gundam Earth Federation Sayla Mass | C26: 21631 | D26: 1 | E26: =D26*C26 | F26: 0 | G26: =F26*C26 | H26: 0 | I26: =H26*C26
A27: 메가하우스 | B27: [메가하우스]GGG MOBILE SUIT Z GUNDAM Quattro Vageena （Limited Repeat） | D27: 9 | E27: =D27*C27 | F27: 0 | G27: =F27*C27 | H27: 0 | I27: =H27*C27
A28: 메가하우스 | B28: [메가하우스]GGG-DX MOBILE SUIT GUNDAM Char Aznable ～Encounters～ | C28: 222445 | D28: 1 | E28: =D28*C28 | F28: 0 | G28: =F28*C28 | H28: 0 | I28: =H28*C28
A29: 메가하우스 | B29: [메가하우스]ISSUXARK | D29: 3 | E29: =D29*C29 | F29: 0 | G29: =F29*C29 | H29: 0 | I29: =H29*C29
A30: 메가하우스 | B30: [메가하우스]Look up Demon Slayer：Kimetsu no Yaiba Nezuko Kamado（Repeat） | C30: 27699 | D30: 6 | E30: =D30*C30 | F30: 0 | G30: =F30*C30 | H30: 0 | I30: =H30*C30
A31: 메가하우스 | B31: [메가하우스]Look up Demon Slayer：Kimetsu no Yaiba Tanjiro Kamado （Repeat） | C31: 27699 | D31: 5 | E31: =D31*C31 | F31: 1 | G31: =F31*C31 | H31: 0 | I31: =H31*C31
A32: 메가하우스 | B32: [메가하우스]Lookup Birth of Kitaro The Mystery of GeGeGe Kitaros dad | C32: 30470 | D32: 1 | E32: =D32*C32 | F32: 0 | G32: =F32*C32 | H32: 0 | I32: =H32*C32
A33: 메가하우스 | B33: [메가하우스]Lookup Birth of Kitaro The Mystery of GeGeGe Kitaros dad&Mizuki set【with gift】 | C33: 71915 | D33: 32 | E33: =D33*C33 | F33: 0 | G33: =F33*C33 | H33: 0 | I33: =H33*C33
A34: 메가하우스 | B34: [메가하우스]Lookup Birth of Kitaro： The Mystery of GeGeGe Mizuki | C34: 30470 | D34: 1 | E34: =D34*C34 | F34: 0 | G34: =F34*C34 | H34: 0 | I34: =H34*C34
A35: 메가하우스 | B35: [메가하우스]Lookup Blue Archive Shiroko & Hoshino set【with gift】 | D35: 16 | E35: =D35*C35 | F35: 0 | G35: =F35*C35 | H35: 0 | I35: =H35*C35
A36: 메가하우스 | B36: [메가하우스]Lookup BLUE LOCK Seishiro Nagi | C36: 26314 | D36: 0 | E36: =D36*C36 | F36: 1 | G36: =F36*C36 | H36: 0 | I36: =H36*C36
A37: 메가하우스 | B37: [메가하우스]Lookup cape Haikyu!! Kuroo Cat | C37: 10904 | D37: 15 | E37: =D37*C37 | F37: 0 | G37: =F37*C37 | H37: 0 | I37: =H37*C37
A38: 메가하우스 | B38: [메가하우스]Lookup cape Haikyu!! Tsumu Fox | C38: 11080 | D38: 5 | E38: =D38*C38 | F38: 0 | G38: =F38*C38 | H38: 0 | I38: =H38*C38
A39: 메가하우스 | B39: [메가하우스]Lookup Chainsaw Man – The Movie： Reze Arc Denji & Reze set【with gift】 | C39: 67916 | D39: 3 | E39: =D39*C39 | F39: 0 | G39: =F39*C39 | H39: 0 | I39: =H39*C39
A40: 메가하우스 | B40: [메가하우스]Lookup Chainsaw Man – The Movie： Reze Arc Reze | C40: 29084 | D40: 30 | E40: =D40*C40 | F40: 2 | G40: =F40*C40 | H40: 0 | I40: =H40*C40
...

Sheet 메가하우스_직영
A1: 재고위치 | B1: 바코드 | C1: 제품명 | D1: 재고수량 | E1: 입고단가 | F1: 재고금액
A2: 매장 | B2: 4535123845208 | C2: 얼티메이트 아티클 가면라이더 블랙 | D2: 1 | E2: 271747 | F2: =D2*E2
A3: 매장 | B3: 4535123843372 | C3: 얼티메이트 아티클 가면라이더 쿠우가 마이티 폼 | D3: 1 | E3: 234684 | F3: =D3*E3
A4: 매장 | B4: 4535123847899 | C4: 룩업 다이컷 스티커 귀멸의 칼날 (총 8종 랜덤) | D4: 288 | E4: 2740 | F4: =D4*E4
A5: 매장 | B5: 8808256024755 | C5: 룩업 다이컷 스티커 귀멸의 칼날 (총 8종 세트) | D5: 26 | E5: 21920 | F5: =D5*E5
A6: 매장 | B6: 4535123847301 | C6: 꺄르르르 아크릴 스탠드 그노시아 | D6: 60 | E6: 5497 | F6: =D6*E6
A7: 매장 | B7: 4535123847318 | C7: 꺄르르르 아크릴 스탠드 그노시아 vol.2 | D7: 68 | E7: 5540 | F7: =D7*E7
A8: 매장 | B8: 4535123844652 | C8: 토코토코 아크릴 스탠드 기동전사 건담 지쿠악스 (6종) | D8: 21 | E8: 5119 | F8: =D8*E8
A9: 매장 | B9: 4535123848032 | C9: 룩업 콜라주 스티커 귀멸의 칼날 주 1 | D9: 231 | E9: 3647 | F9: =D9*E9
A10: 매장 | B10: 4535123844096 | C10: GEM 테노히라 사카모토데이즈 나구모씨 (나구모 요이치) | D10: 5 | E10: 50910 | F10: =D10*E10
A11: 매장 | B11: 4535123834370 | C11: 룩업 블루록 나기 세이시로 | D11: 122 | E11: 26314 | F11: =D11*E11
A12: 매장 | B12: 4535123843181 | C12: 룩업 아이돌리쉬 세븐 나나세 리쿠 | D12: 15 | E12: 28136 | F12: =D12*E12
A13: 매장 | B13: 4535123843204 | C13: 룩업 아이돌리쉬 세븐 나나세 리쿠 & 쿠죠 텐 [특전] | D13: 20 | E13: 66552 | F13: =D13*E13
... A262: 디아이 | B262: 4535123848780 | C262: Chokorin Collection Mr. Ginpachi's Zany Class Vol.2 [6개입] | D262: 2592 | E262: 5891 | F262: =D262*E262
D270: =SUM(D2:D269) | E270: =SUM(E2:E269) | F270: =SUM(F2:F269)

Sheet 부시로드
A1: 브랜드 | B1: 품목명 | C1: 입고단가 | D1: 온라인 수량 | E1: 온라인 재고금액 | F1: 영업 수량 | G1: 영업 재고금액 | H1: 영업_위탁매장 수량 | I1: 영업_위탁매장 재고금액 | J1: 사업지원 수량 | K1: 사업지원 재고금액
A2: 부시로드 | B2: (특전)PalVerse JOJOS BIZARRE ADVENTURE Part3 Stardust Crusaders 【PACK】_【BOX Special Offer】 Rubber Stra | D2: 4 | E2: =D2*C2 | F2: 0 | G2: =F2*C2 | H2: 0 | I2: =H2*C2 | J2: 0 | K2: =J2*C2
A3: 부시로드 | B3: [부시로드] 「BanG Dream! Its MyGO!!!!! Part 1 Spring Sunshine Stray Cats」A3 Matte-processed Poste | D3: 1 | E3: =D3*C3 | F3: 0 | G3: =F3*C3 | H3: 0 | I3: =H3*C3 | J3: 0 | K3: =J3*C3
A4: 부시로드 | B4: [부시로드] 「BanG Dream! Its MyGO!!!!! Part 1 Spring Sunshine Stray Cats」Acrylic Diorama | D4: 30 | E4: =D4*C4 | F4: 0 | G4: =F4*C4 | H4: 0 | I4: =H4*C4 | J4: 0 | K4: =J4*C4
A5: 부시로드 | B5: [부시로드] 「BanG Dream! Its MyGO!!!!! Part 1 Spring Sunshine Stray Cats」Acrylic Keychain | D5: 72 | E5: =D5*C5 | F5: 0 | G5: =F5*C5 | H5: 0 | I5: =H5*C5 | J5: 0 | K5: =J5*C5
A6: 부시로드 | B6: [부시로드] 「BanG Dream! Its MyGO!!!!! Part 1 Spring Sunshine Stray Cats」Can Badge Set | D6: 27 | E6: =D6*C6 | F6: 0 | G6: =F6*C6 | H6: 0 | I6: =H6*C6 | J6: 0 | K6: =J6*C6
A7: 부시로드 | B7: [부시로드] Acrylic Stand Vol.01 Aya Maruyama［Pastel*Paletters] | D7: 1 | E7: =D7*C7 | F7: 0 | G7: =F7*C7 | H7: 0 | I7: =H7*C7 | J7: 0 | K7: =J7*C7
A8: 부시로드 | B8: [부시로드] Acrylic Stand Vol.01 Kasumi Toyama［PoppinParty] | D8: 1 | E8: =D8*C8 | F8: 0 | G8: =F8*C8 | H8: 0 | I8: =H8*C8 | J8: 0 | K8: =J8*C8
A9: 부시로드 | B9: [부시로드] Acrylic Stand Vol.01 LAYER［RAISE A SUILEN] | D9: 5 | E9: =D9*C9 | F9: 0 | G9: =F9*C9 | H9: 0 | I9: =H9*C9 | J9: 0 | K9: =J9*C9
A10: 부시로드 | B10: [부시로드] Acrylic Stand Vol.01 Ran Mitake［Afterglow] | D10: 4 | E10: =D10*C10 | F10: 0 | G10: =F10*C10 | H10: 0 | I10: =H10*C10 | J10: 0 | K10: =J10*C10
A11: 부시로드 | B11: [부시로드] Acrylic Stand Vol.02 LOCK［RAISE A SUILEN] | D11: 4 | E11: =D11*C11 | F11: 0 | G11: =F11*C11 | H11: 0 | I11: =H11*C11 | J11: 0 | K11: =J11*C11
A12: 부시로드 | B12: [부시로드] Acrylic Stand Vol.02 Misaki Okusawa［Hello, Happy World!] | D12: 5 | E12: =D12*C12 | F12: 0 | G12: =F12*C12 | H12: 0 | I12: =H12*C12 | J12: 0 | K12: =J12*C12
A13: 부시로드 | B13: [부시로드] Acrylic Stand Vol.02 Moca Aoba［Afterglow] | D13: 1 | E13: =D13*C13 | F13: 0 | G13: =F13*C13 | H13: 0 | I13: =H13*C13 | J13: 0 | K13: =J13*C13
... A18: 부시로드 | B18: [부시로드] Anime「ATRI -My Dear Moments-」 Acrylic Stand Atri Maid ver. | D18: 2 | E18: =D18*C18 | F18: 0 | G18: =F18*C18 | H18: 0 | I18: =H18*C18 | J18: 0 | K18: =J18*C18
A19: 부시로드 | B19: [부시로드] Anime「BOCCHI THE ROCK!」 BOCCHI Chan Trading Acrylic Stand【PACK】 | C19: 5037 | D19: 6 | E19: =D19*C19 | F19: 0 | G19: =F19*C19 | H19: 0 | I19: =H19*C19 | J19: 0 | K19: =J19*C19
A20: 부시로드 | B20: [부시로드] Anime「BOCCHI THE ROCK!」 Trading Acrylic Key Holder Motif ver.【PACK】 | C20: 3598 | D20: 8 | E20: =D20*C20 | F20: 0 | G20: =F20*C20 | H20: 0 | I20: =H20*C20 | J20: 0 | K20: =J20*C20
A21: 부시로드 | B21: [부시로드] Anime「BOCCHI THE ROCK!」 Trading Bromide【PACK】 | C21: 2519 | D21: 0 | E21: =D21*C21 | F21: 0 | G21: =F21*C21 | H21: 10 | I21: =H21*C21 | J21: 0 | K21: =J21*C21
A22: 부시로드 | B22: [부시로드] Anime「BOCCHI THE ROCK!」 Trading Pick Acrylic Key Holder vol.2【PACK】 | C22: 4318 | D22: 1 | E22: =D22*C22 | F22: 0 | G22: =F22*C22 | H22: 0 | I22: =H22*C22 | J22: 0 | K22: =J22*C22
A23: 부시로드 | B23: [부시로드] BanG Dream! Acrylic Keychain Shokyuusei ver. | D23: 2 | E23: =D23*C23 | F23: 0 | G23: =F23*C23 | H23: 0 | I23: =H23*C23 | J23: 0 | K23: =J23*C23
A24: 부시로드 | B24: [부시로드] BanG Dream! Acrylic Stand MyGO!!!!! Taki Shiina | D24: 1 | E24: =D24*C24 | F24: 0 | G24: =F24*C24 | H24: 0 | I24: =H24*C24 | J24: 0 | K24: =J24*C24
A25: 부시로드 | B25: [부시로드] BanG Dream! Ave Mujica Bromide&Acrylic Case vol.1 | D25: 6 | E25: =D25*C25 | F25: 0 | G25: =F25*C25 | H25: 0 | I25: =H25*C25 | J25: 0 | K25: =J25*C25
A26: 부시로드 | B26: [부시로드] BanG Dream! Bromide&Acrylic Case MyGO!!!!! | D26: 4 | E26: =D26*C26 | F26: 0 | G26: =F26*C26 | H26: 0 | I26: =H26*C26 | J26: 0 | K26: =J26*C26
A27: 부시로드 | B27: [부시로드] BanG Dream! Diorama Acrylic Stand Japanese Western Style ver. Lisa Imai | D27: 5 | E27: =D27*C27 | F27: 0 | G27: =F27*C27 | H27: 0 | I27: =H27*C27 | J27: 0 | K27: =J27*C27
A28: 부시로드 | B28: [부시로드] BanG Dream! Diorama Acrylic Stand Summer Night Party! ver. Chisato Shirasagi | D28: 5 | E28: =D28*C28 | F28: 0 | G28: =F28*C28 | H28: 0 | I28: =H28*C28 | J28: 0 | K28: =J28*C28
A29: 부시로드 | B29: [부시로드] BanG Dream! Extra Large Acrylic Stand Summer Night Party! ver. Touko Kirigaya | D29: 1 | E29: =D29*C29 | F29: 0 | G29: =F29*C29 | H29: 0 | I29: =H29*C29 | J29: 0 | K29: =J29*C29
A30: 부시로드 | B30: [부시로드] BanG Dream! Girls Band Party! Acrylic Keychain Summer Night Party! ver. Chisato Shirasagi | D30: 4 | E30: =D30*C30 | F30: 0 | G30: =F30*C30 | H30: 0 | I30: =H30*C30 | J30: 0 | K30: =J30*C30
A31: 부시로드 | B31: [부시로드] BanG Dream! Girls Band Party! Acrylic Keychain Summer Night Party! ver. Kaoru Seta | D31: 6 | E31: =D31*C31 | F31: 0 | G31: =F31*C31 | H31: 0 | I31: =H31*C31 | J31: 0 | K31: =J31*C31
A32: 부시로드 | B32: [부시로드] BanG Dream! Girls Band Party! Acrylic Keychain Summer Night Party! ver. Kasumi Toyama | D32: 7 | E32: =D32*C32 | F32: 0 | G32: =F32*C32 | H32: 0 | I32: =H32*C32 | J32: 0 | K32: =J32*C32
A33: 부시로드 | B33: [부시로드] BanG Dream! Girls Band Party! Acrylic Keychain Summer Night Party! ver. LOCK | D33: 7 | E33: =D33*C33 | F33: 0 | G33: =F33*C33 | H33: 0 | I33: =H33*C33 | J33: 0 | K33: =J33*C33
A34: 부시로드 | B34: [부시로드] BanG Dream! Girls Band Party! Acrylic Keychain Summer Night Party! ver. Moca Aoba | D34: 6 | E34: =D34*C34 | F34: 0 | G34: =F34*C34 | H34: 0 | I34: =H34*C34 | J34: 0 | K34: =J34*C34
... A49: 부시로드 | B49: [부시로드] BanG Dream! Girls Band Party! Trading Ticket Card Japanese Western Style ver. 【PACK】 | D49: 16 | E49: =D49*C49 | F49: 0 | G49: =F49*C49 | H49: 0 | I49: =H49*C49 | J49: 0 | K49: =J49*C49
A50: 부시로드 | B50: [부시로드] BanG Dream! Its MyGO!!!!! Acrylic Key Holder Anon Chihaya Memorial Art ver. | C50: 7962 | D50: 1 | E50: =D50*C50 | F50: 0 | G50: =F50*C50 | H50: 0 | I50: =H50*C50 | J50: 0 | K50: =J50*C50
A51: 부시로드 | B51: [부시로드] BanG Dream! Its MyGO!!!!! Acrylic Key Holder Rāna Kaname Memorial Art ver. | C51: 7962 | D51: 5 | E51: =D51*C51 | F51: 0 | G51: =F51*C51 | H51: 0 | I51: =H51*C51 | J51: 0 | K51: =J51*C51
A52: 부시로드 | B52: [부시로드] BanG Dream! Its MyGO!!!!! Acrylic Key Holder Soyo Nagasaki Memorial Art ver. | C52: 7962 | D52: 1 | E52: =D52*C52 | F52: 0 | G52: =F52*C52 | H52: 0 | I52: =H52*C52 | J52: 0 | K52: =J52*C52
A53: 부시로드 | B53: [부시로드] BanG Dream! Its MyGO!!!!! Acrylic Key Holder Taki Shiina Memorial Art ver. | C53: 7962 | D53: 13 | E53: =D53*C53 | F53: 0 | G53: =F53*C53 | H53: 0 | I53: =H53*C53 | J53: 0 | K53: =J53*C53
A54: 부시로드 | B54: [부시로드] BanG Dream! Its MyGO!!!!! Acrylic Key Holder Tomori Takamatsu Memorial Art ver. | C54: 7962 | D54: 1 | E54: =D54*C54 | F54: 0 | G54: =F54*C54 | H54: 0 | I54: =H54*C54 | J54: 0 | K54: =J54*C54
A55: 부시로드 | B55: [부시로드] BanG Dream! Its MyGO!!!!! Acrylic Stand Rāna Kaname Memorial Art ver. | C55: 11943 | D55: 14 | E55: =D55*C55 | F55: 0 | G55: =F55*C55 | H55: 0 | I55: =H55*C55 | J55: 0 | K55: =J55*C55
A56: 부시로드 | B56: [부시로드] BanG Dream! Its MyGO!!!!! Acrylic Stand Tomori Takamatsu Memorial Art ver. | C56: 11943 | D56: 8 | E56: =D56*C56 | F56: 0 | G56: =F56*C56 | H56: 0 | I56: =H56*C56 | J56: 0 | K56: =J56*C56
A57: 부시로드 | B57: [부시로드] BanG Dream! Its MyGO!!!!! diorama acrylic stand Rāna Kaname | D57: 1 | E57: =D57*C57 | F57: 0 | G57: =F57*C57 | H57: 0 | I57: =H57*C57 | J57: 0 | K57: =J57*C57
A58: 부시로드 | B58: [부시로드] BanG Dream! Its MyGO!!!!! diorama acrylic stand Taki Shiina | D58: 2 | E58: =D58*C58 | F58: 0 | G58: =F58*C58 | H58: 0 | I58: =H58*C58 | J58: 0 | K58: =J58*C58
...

Sheet 블로키 
A1: 브랜드 | B1: 품목명 | C1: 입고단가 | D1: 온라인 수량 | E1: 온라인 재고금액 | F1: 영업 수량 | G1: 영업 재고금액
A2: 블로키 | B2: [블로키] 나루토 갤럭시 버전 GV02 랜덤 (1박스/9개입) | C2: 54000 | D2: 0 | E2: =D2*C2 | F2: 15 | G2: =F2*C2
A3: 블로키 | B3: [블로키] 나루토 갤럭시 버전 GV03 랜덤 (1박스/9개입) | C3: 54000 | D3: 0 | E3: =D3*C3 | F3: 17 | G3: =F3*C3
A4: 블로키 | B4: [블로키] 나루토 갤럭시 버전 GV04 랜덤 (1박스/9개입) | C4: 54000 | D4: 0 | E4: =D4*C4 | F4: 13 | G4: =F4*C4
A5: 블로키 | B5: [블로키] 나루토 액션에디션 AE01 쿠라마 (1박스/1개입) | C5: 36000 | D5: 6 | E5: =D5*C5 | F5: 0 | G5: =F5*C5
A6: 블로키 | B6: [블로키] 나루토 챔피온클래스 우치하 마다라 CC05 (1박스/1개입) | C6: 16000 | D6: 10 | E6: =D6*C6 | F6: 0 | G6: =F6*C6
A7: 블로키 | B7: [블로키] 사쿠라 미쿠 판타스틱 세런디피티 FS EX02 (1박스/1개입) | C7: 30000 | D7: 8 | E7: =D7*C7 | F7: 0 | G7: =F7*C7
A8: 블로키 | B8: [블로키] 스타워즈 만달로리안 갤럭시 버전 GV01 랜덤 (9종 + 1히든) (1박스/9개입) | C8: 58500 | D8: 0 | E8: =D8*C8 | F8: 2 | G8: =F8*C8
A9: 블로키 | B9: [블로키] 스타워즈 만달로리안 갤럭시 버전 GV02 랜덤 (9종 + 1히든) (1박스/9개입) | C9: 58500 | D9: 0 | E9: =D9*C9 | F9: 1 | G9: =F9*C9
A10: 블로키 | B10: [블로키] 스타워즈 챔피온클래스 CC02 스톰트루퍼 (1박스/1개입) | C10: 14500 | D10: 0 | E10: =D10*C10 | F10: 2 | G10: =F10*C10
A11: 블로키 | B11: [블로키] 스타워즈 챔피온클래스 CC05 딘자린 & 그로구 (1박스/1개입) | C11: 20000 | D11: 0 | E11: =D11*C11 | F11: 4 | G11: =F11*C11
A12: 블로키 | B12: [블로키] 스타워즈 챔피온클래스 CC06 보 카탄 크리즈 (1박스/1개입) | C12: 17000 | D12: 0 | E12: =D12*C12 | F12: 2 | G12: =F12*C12
A13: 블로키 | B13: [블로키] 에반게리온 아스카 시키나미 랭글리 슈트버전 FF01 (1박스/1개입) | C13: 27500 | D13: 6 | E13: =D13*C13 | F13: 0 | G13: =F13*C13
... A17: 블로키 | B17: [블로키] 에반게리온 액션에디션 초호기 AE01 (1박스/1개입) | C17: 27500 | D17: 4 | E17: =D17*C17 | F17: 0 | G17: =F17*C17
A18: 블로키 | B18: [블로키] 주토피아 DD-ART01 마시멜로우 키링 랜덤 (6종 + 1히든) (1박스/6개입) | D18: 0 | E18: =D18*C18 | F18: 11 | G18: =F18*C18
A19: 블로키 | B19: [블로키] 주토피아 DD-MATE01 엠블럼 랜덤 (6종 + 1히든) (1박스/6개입) | D19: 0 | E19: =D19*C19 | F19: 1 | G19: =F19*C19
A20: 블로키 | B20: [블로키] 쥬라기공원 테라벤처 TS01 (12종 + 2히든) (1박스/12개입) | C20: 30000 | D20: 0 | E20: =D20*C20 | F20: 10 | G20: =F20*C20
A21: 블로키 | B21: [블로키] 쥬라기공원 테라벤처 TS02 (12종 + 2히든) (1박스/12개입) | C21: 30000 | D21: 0 | E21: =D21*C21 | F21: 10 | G21: =F21*C21
A22: 블로키 | B22: [블로키] 쥬라기공원 테라벤처 TS03 (12종 + 2히든) (1박스/12개입) | C22: 30000 | D22: 0 | E22: =D22*C22 | F22: 10 | G22: =F22*C22
A23: 블로키 | B23: [블로키] 토이스토라 키캡 / 반지 DD-FUN01 12in1 (1박스/12개입) | C23: 42000 | D23: 0 | E23: =D23*C23 | F23: 25 | G23: =F23*C23
A24: 블로키 | B24: [블로키] 하츠네 미쿠 판타스틱 세런디피티 FS EX01 (1박스/1개입) | C24: 30000 | D24: 10 | E24: =D24*C24 | F24: 0 | G24: =F24*C24
A25: 블로키 | B25: [블로키] 하츠네미쿠 WITH YOU DLM-Q01 랜덤 (6종) (1박스/6개입) | C25: 72000 | D25: 9 | E25: =D25*C25 | F25: 16 | G25: =F25*C25
A26: 블로키 | B26: [블로키] 하츠네미쿠 WithYou 판타스틱시리즈 FF04 (1박스/1개입) | C26: 39000 | D26: 7 | E26: =D26*C26 | F26: 1 | G26: =F26*C26
A27: 블로키 | B27: [블로키] 하츠네미쿠 소나타 프롤로그 DLM12 01 랜덤 (1박스/6개입) | C27: 99000 | D27: 10 | E27: =D27*C27 | F27: 19 | G27: =F27*C27
A28: 블로키 | B28: [블로키] 하츠네미쿠 테라스파티 DVB01 랜덤 (6종 + 1히든) (1박스/6개입) | C28: 63000 | D28: 12 | E28: =D28*C28 | F28: 9 | G28: =F28*C28
D29: 0 | F29: 0
D30: 0 | F30: 0
D31: 0 | E31: =SUM(E2:E30) | F31: 0 | G31: =SUM(G2:G30)

Sheet 반다이남코
A1: 브랜드 | B1: 품목명 | C1: 입고단가 | D1: 온라인 수량 | E1: 온라인 재고금액 | F1: 영업 수량 | G1: 영업 재고금액
A2: 반다이남코 | B2: [반다이남코 상하이] BN HEAD Collection MS-06F 양산형 자쿠 Ⅱ (1박스/1개입) | C2: 161000 | D2: 0 | E2: =D2*C2 | F2: 4 | G2: =F2*C2
A3: 반다이남코 | B3: [반다이남코 상하이] QMSV MINI 5주년 아티스트 컬러 Ver. (1박스/8개) | D3: 5 | E3: =D3*C3 | F3: 9 | G3: =F3*C3
A4: 반다이남코 | B4: [반다이남코 상하이] QMSV MINI GOLD TEAM(미정) (1박스/8개입) | C4: 43648 | D4: 0 | E4: =D4*C4 | F4: 8 | G4: =F4*C4
A5: 반다이남코 | B5: [반다이남코 상하이] QMSV MINI Z 건담 & 건담 마크 II (1박스/8pcs) | D5: 20 | E5: =D5*C5 | F5: 36 | G5: =F5*C5
A6: 반다이남코 | B6: [반다이남코 상하이]QMSV MINI 건담 시드 프리덤 (1박스/8개입) | C6: 13827 | D6: 3 | E6: =D6*C6 | F6: 0 | G6: =F6*C6
A7: 반다이남코 | B7: [반다이남코] bitlot 건담 2 (1박스/10개입) | D7: 0 | E7: =D7*C7 | F7: 8 | G7: =F7*C7
A8: 반다이남코 | B8: [반다이남코] BN FIGURE Q 기동전사 건담 SEED DESTINY 파자마즈 Ver. (1박스/6pcs) | D8: 50 | E8: =D8*C8 | F8: 92 | G8: =F8*C8
A9: 반다이남코 | B9: [반다이남코] CONVERGE 가면라이더 30 (1박스/10개입) | D9: 0 | E9: =D9*C9 | F9: 0 | G9: =F9*C9
A10: 반다이남코 | B10: [반다이남코] FW 건담 컨버지 #27(1박스/10개단위) | D10: 0 | E10: =D10*C10 | F10: 1 | G10: =F10*C10
A11: 반다이남코 | B11: [반다이남코] FW 건담 컨버지 #28(1박스/10개입) | D11: 5 | E11: =D11*C11 | F11: 5 | G11: =F11*C11
A12: 반다이남코 | B12: [반다이남코] FW건담컨버지코어 시드 프리덤 리바이브 라이징&이모탈 | C12: 22680 | D12: 3 | E12: =D12*C12 | F12: 3 | G12: =F12*C12
A13: 반다이남코 | B13: [반다이남코] FW건담컨버지코어 시드 프리덤 리바이브 마이티 | C13: 21000 | D13: 3 | E13: =D13*C13 | F13: 3 | G13: =F13*C13
A14: 반다이남코 | B14: [반다이남코] GUNDAM 건프라 패키지 아트 구미 3 (1박스/20개입) | C14: 31460 | D14: 0 | E14: =D14*C14 | F14: 3 | G14: =F14*C14
A15: 반다이남코 | B15: [반다이남코] POTEPOTTE-R 기동전사 건담 GQuuuuuuX (1박스/10개입) | C15: 97680 | D15: 0 | E15: =D15*C15 | F15: 13 | G15: =F15*C15
A16: 반다이남코 | B16: [반다이남코] QMSV mini STRIKE & DESTINY GUNDAM (1박스/8개입) | C16: 110880 | D16: 0 | E16: =D16*C16 | F16: 15 | G16: =F16*C16
A17: 반다이남코 | B17: [반다이남코] Re:제로부터 시작하는 이세계 생활 웨하스 5 (1박스/20pcs) | D17: 20 | E17: =D17*C17 | F17: 0 | G17: =F17*C17
A18: 반다이남코 | B18: [반다이남코] S.H.피규아트 우마무스메 프리티더비 키타산 블랙 | C18: 71225 | D18: 0 | E18: =D18*C18 | F18: 2 | G18: =F18*C18
A19: 반다이남코 | B19: [반다이남코] SMP [SHOKUGAN MODELING PROJECT] 볼테스 V 레거시 | D19: 3 | E19: =D19*C19 | F19: 5 | G19: =F19*C19
A20: 반다이남코 | B20: [반다이남코] SMP [SHOKUGAN MODELING PROJECT] 슈퍼로봇대전 OG R-1改 | C20: 44310 | D20: 5 | E20: =D20*C20 | F20: 5 | G20: =F20*C20
A21: 반다이남코 | B21: [반다이남코] SMP [SHOKUGAN MODELING PROJECT] 용자경찰 제이데커 듀크 파이어 | C21: 75600 | D21: 0 | E21: =D21*C21 | F21: 0 | G21: =F21*C21
A22: 반다이남코 | B22: [반다이남코] SMP [SHOKUGAN MODELING PROJECT] 용자왕 가오가이거 파이널・가오가이거 골드Ver. | C22: 227570 | D22: 2 | E22: =D22*C22 | F22: 0 | G22: =F22*C22
A23: 반다이남코 | B23: [반다이남코] SMP [SHOKUGAN MODELING PROJECT] 전설의 용자 다간 (1박스/1개입) | C23: 63830 | D23: 35 | E23: =D23*C23 | F23: 24 | G23: =F23*C23
A24: 반다이남코 | B24: [반다이남코] SMP [SHOKUGAN MODELING PROJECT] 전설의 용자 다간 (특전) | D24: 35 | E24: =D24*C24 | F24: 24 | G24: =F24*C24
A25: 반다이남코 | B25: [반다이남코] SMP [SHOKUGAN MODELING PROJECT] 톱을 노려라! 건버스터 | D25: 6 | E25: =D25*C25 | F25: 0 | G25: =F25*C25
A26: 반다이남코 | B26: [반다이남코] SMP [SHOKUGAN MODELING PROJECT] 투장 다이모스 | C26: 68040 | D26: 3 | E26: =D26*C26 | F26: 5 | G26: =F26*C26
A27: 반다이남코 | B27: [반다이남코] SMP [SHOKUGAN MODELING PROJECT] 황금용자 골드런 | D27: 3 | E27: =D27*C27 | F27: 0 | G27: =F27*C27
A28: 반다이남코 | B28: [반다이남코] SMP ALTERNATIVE DESTINY 초수기신 단쿠가 단쿠가 (1박스/1개입) | C28: 83860 | D28: 2 | E28: =D28*C28 | F28: 0 | G28: =F28*C28
A29: 반다이남코 | B29: [반다이남코] SMP스토리지 컬렉션 (1박스/6단위) | D29: 0 | E29: =D29*C29 | F29: 3 | G29: =F29*C29
A30: 반다이남코 | B30: [반다이남코] TV애니메이션 단다단 카드 웨하스 (1박스/20개입) | D30: 0 | E30: =D30*C30 | F30: 3 | G30: =F30*C30
A31: 반다이남코 | B31: [반다이남코] WIND BREAKER 웨하스 2 (1박스/20pcs) | D31: 10 | E31: =D31*C31 | F31: 0 | G31: =F31*C31
A32: 반다이남코 | B32: [반다이남코] 기동전사 건담 G프레임 FA 08(1박스/12개입) | D32: 5 | E32: =D32*C32 | F32: 3 | G32: =F32*C32
A33: 반다이남코 | B33: [반다이남코] 기동전사 건담 G프레임 FA 09 (1박스/12개입) | C33: 64020 | D33: 0 | E33: =D33*C33 | F33: 5 | G33: =F33*C33
A34: 반다이남코 | B34: [반다이남코] 기동전사 건담 지쿠악스 카드 웨하스 (1박스/20pcs) | D34: 19 | E34: =D34*C34 | F34: 21 | G34: =F34*C34
A35: 반다이남코 | B35: [반다이남코] 기동전사 건담G프레임 FA 07 (1박스/12단위) | D35: 2 | E35: =D35*C35 | F35: 2 | G35: =F35*C35
A36: 반다이남코 | B36: [반다이남코] 너랑 아이돌 프리큐어 스위트 펄 돌 2 (1박스/10개입) | D36: 0 | E36: =D36*C36 | F36: 5 | G36: =F36*C36
A37: 반다이남코 | B37: [반다이남코] 너와 아이돌 프리큐어 마스코트 (1박스/10pcs) | D37: 20 | E37: =D37*C37 | F37: 38 | G37: =F37*C37
A38: 반다이남코 | B38: [반다이남코] 니지산지 웨하스 (1박스/20개입) | D38: 0 | E38: =D38*C38 | F38: 5 | G38: =F38*C38
A39: 반다이남코 | B39: [반다이남코] 니지산지 웨하스 2 (1박스/20개입) | C39: 37840 | D39: 0 | E39: =D39*C39 | F39: 4 | G39: =F39*C39
A40: 반다이남코 | B40: [반다이남코] 니포르메이션 극장판 하이큐 쓰레기장의 결전 씰 웨하스 (1박스/20개입) | D40: 0 | E40: =D40*C40 | F40: 4 | G40: =F40*C40
...

Sheet 핫토이_온라인
A1: 브랜드 | B1: 품목명 | C1: 입고단가 | D1: 온라인 수량 | E1: 온라인 재고금액
A2: 핫토이 | B2: [한정판] 핫토이 MMS697 1/6 WB 100 배트맨 | C2: 331000 | D2: 1 | E2: =D2*C2
A3: 핫토이 | B3: COSB478 인크레더블 잭잭 레이저 아이즈 코스베이비 | C3: 14000 | D3: 2 | E3: =D3*C3
A4: 핫토이 | B4: COSB480 인크레더블2 코스베이비 세트 | C4: 71000 | D4: 2 | E4: =D4*C4
A5: 핫토이 | B5: COSB484 핫토이 데드풀2 코스베이비-요리사 | C5: 14000 | D5: 17 | E5: =D5*C5
A6: 핫토이 | B6: COSB485 핫토이 데드풀2 코스베이비-독서 | C6: 14000 | D6: 6 | E6: =D6*C6
A7: 핫토이 | B7: COSB487 블랙펜서 모우비 블랙펜서 2종 세트 | C7: 29000 | D7: 1 | E7: =D7*C7
A8: 핫토이 | B8: COSB490 와스프 3종 세트 앤트맨&와스프 코스베이비 | C8: 23000 | D8: 3 | E8: =D8*C8
A9: 핫토이 | B9: COSB495 어벤저스인피니티워 스타로드 | D9: 1 | E9: =D9*C9
A10: 핫토이 | B10: COSB522 이요-위니더푸 코스베이비 | C10: 19100 | D10: 1 | E10: =D10*C10
A11: 핫토이 | B11: COSB555 캡틴아메리카 (언마스크 버전) : 어벤저스 앤드게임 | C11: 16000 | D11: 1 | E11: =D11*C11
A12: 핫토이 | B12: COSB579 로키(어벤져스 버전) 코스베이비 어벤져스:엔드게임 | C12: 18000 | D12: 2 | E12: =D12*C12
A13: 핫토이 | B13: COSB591 캡틴마블 (메탈릭 컬러 버전) : 어벤저스 앤드게임 | C13: 21000 | D13: 3 | E13: =D13*C13
A14: 핫토이 | B14: COSB749 The Child Cosbaby (L) Bobble-Head | C14: 81200 | D14: 1 | E14: =D14*C14
A15: 핫토이 | B15: MMS505 1/6 데드풀 (더스티 버전) : 데드풀2 | C15: 240000 | D15: 1 | E15: =D15*C15
A16: 핫토이 | B16: MMS600 Iron Man 2 - 1/6th scale Tony Stark (Mark V Suit up Version) (Deluxe Version) | C16: 388000 | D16: 1 | E16: =D16*C16
A17: 핫토이 | B17: MMS658 - The Amazing Spider-Man 2 - 1/6th scale The Amazing Spider-Man Collectible Figure | C17: 290000 | D17: 1 | E17: =D17*C17
A18: 핫토이 | B18: MMS663 - Thor: Love and Thunder - 1/6th scale Mighty Thor Collectible Figure | C18: 314000 | D18: 1 | E18: =D18*C18
A19: 핫토이 | B19: MMS672D50 Iron Man 2 - 1/6th scale Neon Tech Iron Man with Suit – Up Gantry Collectible Set | C19: 758000 | D19: 1 | E19: =D19*C19
A20: 핫토이 | B20: MMS673 - Thor: Love and Thunder - 1/6th scale Valkyrie Collectible Figure | C20: 296000 | D20: 1 | E20: =D20*C20
A21: 핫토이 | B21: MMS684 - Avatar: The Way of Water - 1/6th scale Jake Sully Collectible Figure (Deluxe Version) | C21: 418000 | D21: 1 | E21: =D21*C21
A22: 핫토이 | B22: MMS686 - Avatar: The Way of Water - 1/6th scale Neytiri Collectible Figure (Deluxe Version) | C22: 418000 | D22: 2 | E22: =D22*C22
A23: 핫토이 | B23: MMS690 - Ant-Man and the Wasp: Quantumania - 1/6th scale Ant-Man Collectible Figure | D23: 6 | E23: =D23*C23
A24: 핫토이 | B24: MMS693 - Batman (1989) - 1/6th scale Batman Collectible Figure (Deluxe Version) | C24: 381000 | D24: 1 | E24: =D24*C24
A25: 핫토이 | B25: MMS702 - The Dark Knight Rises - 1/6th scale Batman Armory with Bruce Wayne Collectible Set | D25: 3 | E25: =D25*C25
A26: 핫토이 | B26: MMS707 - Guardians of the Galaxy Vol. 3 - 1/6th scale Groot Collectible Figure (Deluxe Version) | C26: 371000 | D26: 5 | E26: =D26*C26
A27: 핫토이 | B27: MMS708 - Guardians of the Galaxy Vol. 3 - 1/6th scale Rocket and Cosmo Collectible Set | C27: 305000 | D27: 1 | E27: =D27*C27
A28: 핫토이 | B28: MMS714 - Guardians of the Galaxy Vol. 3 - 1/6th scale Nebula Collectible Figure | D28: 4 | E28: =D28*C28
A29: 핫토이 | B29: TMS083 - Star Wars: Obi-Wan Kenobi - 1/6th scale Reva (Third Sister) Collectible Figure | C29: 271000 | D29: 1 | E29: =D29*C29
A30: 핫토이 | B30: VGM53 - Star Wars Jedi Survivor™ - 1/6th scale Scout Trooper Commander™ Collectible Figure | C30: 254000 | D30: 1 | E30: =D30*C30
A31: 핫토이 | B31: 스파이더맨 : 뉴 유니버스 - 스파이더 햄 COSB639 | C31: 18900 | D31: 1 | E31: =D31*C31
A32: 핫토이 | B32: 스파이더맨 : 뉴 유니버스 - 페니 파커&Sp//dr COSB641 | C32: 28700 | D32: 3 | E32: =D32*C32
A33: 핫토이 | B33: 핫토이 COSB646 코스베이비 아이언맨버전 나노건틀렛 | C33: 22000 | D33: 2 | E33: =D33*C33
A34: 핫토이 | B34: 핫토이 COSB663 캡틴마블 코스베이비 엔드게임 | C34: 20600 | D34: 2 | E34: =D34*C34
A35: 핫토이 | B35: 핫토이 DS001C - 7 홀 오브 아머: 아이언맨2[피규어미포함] IRON MAN 2 HALL OF ARMOR 1/6TH SCALE COLLECTIBLE | D35: 1 | E35: =D35*C35
A36: 핫토이 | B36: 핫토이 MMS278D09 마크43 다이캐스트(헐크버스터 미포함) | C36: 315000 | D36: 1 | E36: =D36*C36
A37: 핫토이 | B37: 핫토이 MMS500D27 아이언맨 마크7 어벤져스 1/6 스케일 다이캐스트 피규어 | C37: 377500 | D37: 3 | E37: =D37*C37
A38: 핫토이 | B38: 핫토이 배트맨 다크 나이트 COSB723 배트맨 심문버전 코스베이비Batman (Interrogating Version) Cosbaby (S) | C38: 19400 | D38: 1 | E38: =D38*C38
A39: 핫토이 | B39: 핫토이 배트맨 리턴 COSB715 캣우먼 Cosbaby - Batman Returns - Catwoman Collectible Set Bobble-Head (S) | C39: 25800 | D39: 2 | E39: =D39*C39
A40: 핫토이 | B40: 핫토이 배트맨 리턴 COSB716 캣우먼과 채찍 | C40: 26300 | D40: 1 | E40: =D40*C40
...

Sheet 하비재팬
A1: 브랜드 | B1: 품목명 | C1: 입고단가 | D1: 온라인 수량 | E1: 온라인 재고금액
A2: 하비재팬 | B2: [하비재팬]1/144 VAX-01 VALREIN | D2: 95 | E2: =D2*C2
A3: 하비재팬 | B3: [하비재팬]BOMBERGIRL パイン サキュバスチアコスVer. | C3: 254972 | D3: 6 | E3: =D3*C3
A4: 하비재팬 | B4: [하비재팬]BOMBERGIRL プルーン サキュバスチアコスVer. | D4: 2 | E4: =D4*C4
A5: 하비재팬 | B5: [하비재팬]Goddess of Victory: Nikke Mast：Ａ Pirate‘s Heart | D5: 1 | E5: =D5*C5
A6: 하비재팬 | B6: [하비재팬]PHANTASY STAR ONLINE 2 es Akhtal Summer Vacation | D6: 4 | E6: =D6*C6
A7: 하비재팬 | B7: [하비재팬]ブルーアーカイブ -Blue Archive- ノノミ(水着) | C7: 190209 | D7: 164 | E7: =D7*C7
A8: 하비재팬 | B8: 勝利の女神：NIKKE アリス スイートホーム | C8: 185872 | D8: 2 | E8: =D8*C8
D9: 0
D10: 0
D11: 0 | E11: =SUM(E2:E10)
D12: 0
D13: 0
A14: 하비재팬 | B14: [하비재팬]GUILTY GEAR XX Λ CORE PLUS R Bridget | D14: 1 | E14: =D14*C14

Sheet CCS 
A1: 브랜드 | B1: 품목명 | C1: 입고단가 | D1: 온라인 수량 | E1: 온라인 재고금액
A2: CCS TOYS | B2: CCS EVANGELIOM FINAL MODEL（ULTIMUS EDITION） | C2: 271138 | D2: 173 | E2: =D2*C2
A3: CCS TOYS | B3: CCS EVANGELION Unit-02 Type II | D3: 837 | E3: =D3*C3
A4: CCS TOYS | B4: CCS 그레이트 마징카이저 | D4: 1 | E4: =D4*C4
D5: 0
D6: 0
D7: 0
D8: 0 | E8: =SUM(E2:E7)

Sheet P001 온라인
A1: 브랜드 | B1: 품목명 | C1: 입고단가 | D1: 온라인 수량
A2: P001 | B2: P001 태권브이 3종 세트 | D2: 533

Sheet 코코파
A1: 브랜드 | B1: 품목명 | C1: 입고단가 | D1: 온라인 수량 | E1: 온라인 재고금액
A2: 코코파 | B2: 코코파 스튜디오 DEFORMED WORLD 마징가 Z | C2: 92032 | D2: 21 | E2: =D2*C2
D3: 0
D4: 0
D5: 0

Sheet 미쿠감사제
A1: 브랜드 | B1: 품목명 | C1: 입고단가 | D1: 컨기 수량 | E1: 컨기 재고금액
A2: 미쿠감사제_2026 | B2: 26년 하츠네미쿠 A3 포스터_같이 듣자 | C2: 773 | D2: 177 | E2: =D2*C2
A3: 미쿠감사제_2026 | B3: 26년 하츠네미쿠 A4 CLEAR FILE_A | C3: 306 | D3: 350 | E3: =D3*C3
A4: 미쿠감사제_2026 | B4: 26년 하츠네미쿠 A4 CLEAR FILE_B | C4: 306 | D4: 273 | E4: =D4*C4
A5: 미쿠감사제_2026 | B5: 26년 하츠네미쿠 A4 CLEAR FILE_C | C5: 306 | D5: 357 | E5: =D5*C5
A6: 미쿠감사제_2026 | B6: 26년 하츠네미쿠 A4 CLEAR FILE_D | C6: 306 | D6: 57 | E6: =D6*C6
A7: 미쿠감사제_2026 | B7: 26년 하츠네미쿠 ACRYLIC BLOCK | C7: 3025 | D7: 206 | E7: =D7*C7
A8: 미쿠감사제_2026 | B8: 26년 하츠네미쿠 ACRYLIC KEYCHAIN_A | C8: 1355 | D8: 525 | E8: =D8*C8
A9: 미쿠감사제_2026 | B9: 26년 하츠네미쿠 ACRYLIC KEYCHAIN_B | C9: 1355 | D9: 232 | E9: =D9*C9
A10: 미쿠감사제_2026 | B10: 26년 하츠네미쿠 ACRYLIC KEYCHAIN_C | C10: 1355 | D10: 542 | E10: =D10*C10
A11: 미쿠감사제_2026 | B11: 26년 하츠네미쿠 B2 TAPESTRY_A | C11: 4402 | D11: 61 | E11: =D11*C11
A12: 미쿠감사제_2026 | B12: 26년 하츠네미쿠 B2 TAPESTRY_B | C12: 4402 | D12: 42 | E12: =D12*C12
A13: 미쿠감사제_2026 | B13: 26년 하츠네미쿠 CAN BADGE STAND_A | C13: 2565 | D13: 76 | E13: =D13*C13
... A27: 미쿠감사제_2026 | B27: 26년 하츠네미쿠 표정 모음 스티커 | C27: 427 | D27: 1031 | E27: =D27*C27
D28: 0
D29: 0
D30: 0 | E30: =SUM(E2:E29)
A31: 미쿠감사제_2026 | B31: 26년 하츠네미쿠 PLUSH MIKU | C31: 6165 | D31: 11 | E31: =D31*C31
A32: 미쿠감사제_2026 | B32: 26년 하츠네미쿠 FACE CUSHION | C32: 9247 | D32: 7 | E32: =D32*C32
A33: 미쿠감사제_2026 | B33: 26년 하츠네미쿠 PLUSH KEYCHAIN | C33: 4484 | D33: 10 | E33: =D33*C33
A34: 미쿠감사제_2026 | B34: 26년 하츠네미쿠 DIORAMA ACRYLIC STAND_B | C34: 6437 | D34: 12 | E34: =D34*C34
A35: 미쿠감사제_2026 | B35: 26년 하츠네미쿠 ACRYLIC LED FRAME | C35: 9298 | D35: 10 | E35: =D35*C35
A36: 미쿠감사제_2026 | B36: 26년 하츠네미쿠 ACRYLIC KEYCHAIN_D | C36: 1355 | D36: 11 | E36: =D36*C36
A37: 미쿠감사제_2026 | B37: 26년 하츠네미쿠 ACRYLIC PHOTO CARD SET | C37: 3388 | D37: 6 | E37: =D37*C37
A38: 미쿠감사제_2026 | B38: 26년 하츠네미쿠 A3 포스터_26년 감사제 | C38: 773 | D38: 3 | E38: =D38*C38
A39: 미쿠감사제_2026 | B39: 26년 하츠네미쿠 A3 포스터_즐거운 시간 | C39: 773 | D39: 3 | E39: =D39*C39
A40: 미쿠감사제_2026 | B40: 26년 하츠네미쿠 A3 포스터_같이 가자 | C40: 773 | D40: 3 | E40: =D40*C40
A41: 미쿠감사제_2026 | B41: 26년 하츠네미쿠 스티커_26년 감사제 | C41: 427 | D41: 3 | E41: =D41*C41
A42: 미쿠감사제_2026 | B42: 26년 하츠네미쿠 스티커_즐거운 시간 | C42: 427 | D42: 3 | E42: =D42*C42
... A60: 미쿠감사제_2026 | B60: 26년 하츠네미쿠 PaperBag | C60: 1388 | D60: 513 | E60: =D60*C60
A61: 미쿠감사제_2026 | B61: 26년 하츠네미쿠 특전_하츠네 미쿠 티켓_26년 감사제 | D61: 162 | E61: =D61*C61
A62: 미쿠감사제_2026 | B62: 26년 하츠네미쿠 특전_하츠네 미쿠 티켓_즐거운 시간 | D62: 114 | E62: =D62*C62
A63: 미쿠감사제_2026 | B63: 26년 하츠네미쿠 특전_하츠네 미쿠 티켓_같이 듣자 | D63: 113 | E63: =D63*C63
A64: 미쿠감사제_2026 | B64: 26년 하츠네미쿠 특전_하츠네 미쿠 티켓_같이 가자 | D64: 171 | E64: =D64*C64
A65: 미쿠감사제_2026 | B65: 26년 하츠네미쿠 특전_하츠네 미쿠 포토카드_윙크 미쿠 | D65: 915 | E65: =D65*C65
A66: 미쿠감사제_2026 | B66: 26년 하츠네미쿠 특전_하츠네 미쿠 포토카드_선글라스 미쿠 | D66: 941 | E66: =D66*C66
A67: 미쿠감사제_2026 | B67: 26년 하츠네미쿠 특전_하츠네 미쿠 포토카드_피아프로 미쿠 | D67: 1072 | E67: =D67*C67
A68: 미쿠감사제_2026 | B68: 하츠네 미쿠 페이스 쿠션 | C68: 10154 | D68: 10 | E68: =D68*C68
A69: 미쿠감사제_2026 | B69: 하츠네 미쿠 안아줘 인형 | C69: 7615 | D69: 3 | E69: =D69*C69
A70: 미쿠감사제_2026 | B70: 하츠네 미쿠 페이스 봉제 인형 키링_빤히 미쿠 | C70: 4062 | D70: 3 | E70: =D70*C70
...

Sheet 기타브랜드
A1: 브랜드 | B1: 품목명 | C1: 입고단가 | D1: 온라인 수량 | E1: 온라인 재고금액 | F1: 영업 수량 | G1: 영업 재고금액
A2: 기타브랜드 | B2: [ANIPLEX] [귀멸의 칼날] 아크릴 스탠드 <츠유리 카나오> | C2: 12600 | D2: 0 | E2: =D2*C2 | F2: 9 | G2: =F2*C2
A3: 기타브랜드 | B3: [ANIPLEX] [귀멸의 칼날] 아크릴 스탠드 <코쵸우 시노부> | C3: 12600 | D3: 0 | E3: =D3*C3 | F3: 8 | G3: =F3*C3
A4: 기타브랜드 | B4: [ANIPLEX] [귀멸의 칼날] 아크릴 스탠드 <토미오카 기유> | C4: 12600 | D4: 0 | E4: =D4*C4 | F4: 20 | G4: =F4*C4
A5: 기타브랜드 | B5: [Furai Action] Leo Prime | C5: 100585 | D5: 2 | E5: =D5*C5 | F5: 0 | G5: =F5*C5
A6: 기타브랜드 | B6: [NULL SET] [하이큐!!] SD 투명 칼선 스티커 카라스노 A | C6: 2340 | D6: 0 | E6: =D6*C6 | F6: 5 | G6: =F6*C6
A7: 기타브랜드 | B7: [NULL SET] [하이큐!!] 경기 스틸컷 엽서 6종 컬렉션 후쿠로다니 ver. | C7: 9540 | D7: 0 | E7: =D7*C7 | F7: 4 | G7: =F7*C7
A8: 기타브랜드 | B8: [NULL SET] [하이큐!!] 레이저 티켓 / 보쿠토 | C8: 3540 | D8: 0 | E8: =D8*C8 | F8: 5 | G8: =F8*C8
A9: 기타브랜드 | B9: [NULL SET] [하이큐!!] 마츠리 아크릴 스탠드 / 니시노야&타나카 | C9: 22500 | D9: 0 | E9: =D9*C9 | F9: 6 | G9: =F9*C9
A10: 기타브랜드 | B10: [NULL SET] [하이큐!!] 마츠리 아크릴 스탠드 / 사와무라&스가와라 | C10: 22500 | D10: 0 | E10: =D10*C10 | F10: 2 | G10: =F10*C10
A11: 기타브랜드 | B11: [NULL SET] [하이큐!!] 마츠리 아크릴 스탠드 / 츠키시마&야마구치 | C11: 22500 | D11: 0 | E11: =D11*C11 | F11: 3 | G11: =F11*C11
A12: 기타브랜드 | B12: [NULL SET] [하이큐!!] 워밍업 PP포스터 / 츠키시마 | C12: 5340 | D12: 0 | E12: =D12*C12 | F12: 7 | G12: =F12*C12
A13: 기타브랜드 | B13: [NULL SET] [하이큐!!] 트윈 아크릴 스탠드 / 츠키시마&야마구치 | C13: 17340 | D13: 0 | E13: =D13*C13 | F13: 1 | G13: =F13*C13
... A26: 기타브랜드 | B26: [SMG] [하이큐!!] HINO 全國必勝 PP포스터 2종 세트 / 쿠로오&켄마 | C26: 9900 | D26: 0 | E26: =D26*C26 | F26: 1 | G26: =F26*C26
A27: 기타브랜드 | B27: [SMG] Half body stand series-Aira | D27: 0 | E27: =D27*C27 | F27: 20 | G27: =F27*C27
A28: 기타브랜드 | B28: [SMG] Half body stand series-Jiji | D28: 0 | E28: =D28*C28 | F28: 20 | G28: =F28*C28
A29: 기타브랜드 | B29: [SMG] Half body stand series-Momo | D29: 0 | E29: =D29*C29 | F29: 10 | G29: =F29*C29
A30: 기타브랜드 | B30: [SMG] Half body stand series-Okarun | D30: 0 | E30: =D30*C30 | F30: 10 | G30: =F30*C30
A31: 기타브랜드 | B31: [미쿠 콜라보] SD 아크릴스탠드 - 렌 | D31: 0 | E31: =D31*C31 | F31: 3 | G31: =F31*C31
A32: 기타브랜드 | B32: [산엑스]리락쿠마 멋진 우리집 테마 테노리 인형 리락쿠마 | C32: 11000 | D32: 0 | E32: =D32*C32 | F32: 5 | G32: =F32*C32
A33: 기타브랜드 | B33: [산엑스]리락쿠마 멋진 우리집 테마 테노리 인형 챠이로이코구마 | C33: 11000 | D33: 0 | E33: =D33*C33 | F33: 3 | G33: =F33*C33
A34: 기타브랜드 | B34: [산엑스]리락쿠마 베이직 플라워 모찌모찌 쿠션 | C34: 25850 | D34: 0 | E34: =D34*C34 | F34: 3 | G34: =F34*C34
A35: 기타브랜드 | B35: [산엑스]리락쿠마 봉제 카드 케이스 리락쿠마 | C35: 14300 | D35: 0 | E35: =D35*C35 | F35: 4 | G35: =F35*C35
A36: 기타브랜드 | B36: [산엑스]코구마 인형 S | C36: 9900 | D36: 0 | E36: =D36*C36 | F36: 3 | G36: =F36*C36
A37: 기타브랜드 | B37: [센티넬] 에볼루션토이 슈퍼 메탈 액션 태양의 용자 파이버드 제트 합체 그랑버드 - 574186 | C37: 376008 | D37: 1 | E37: =D37*C37 | F37: 0 | G37: =F37*C37
A38: 기타브랜드 | B38: [애니플러스] 블루록 2기 콜라보카페 트레이딩 증명사진 세트 (전8종) | C38: 3250 | D38: 0 | E38: =D38*C38 | F38: 18 | G38: =F38*C38
A39: 기타브랜드 | B39: [애니플러스] 지박소년 하나코 군 2기 콜라보카페 금박 북마크 3종 세트 (1개3매입) | C39: 5200 | D39: 0 | E39: =D39*C39 | F39: 0 | G39: =F39*C39
A40: 기타브랜드 | B40: [애니플렉스] 애니메이션「봇치더록」 고토 히토리 1/7 스케일 피규어 | D40: 2 | E40: =D40*C40 | F40: 0 | G40: =F40*C40
A41: 기타브랜드 | B41: [애니플렉스][ANIPLEX] 귀멸의 칼날 아크릴 참 아카자 | C41: 9800 | D41: 0 | E41: =D41*C41 | F41: 4 | G41: =F41*C41
A42: 기타브랜드 | B42: [애니플렉스][ANIPLEX] 귀멸의 칼날 아크릴 참 카이가쿠 | C42: 9800 | D42: 0 | E42: =D42*C42 | F42: 3 | G42: =F42*C42
A43: 기타브랜드 | B43: [애니플렉스][ANIPLEX] 귀멸의 칼날 아크릴 참 키부츠지 무잔 | C43: 9800 | D43: 0 | E43: =D43*C43 | F43: 3 | G43: =F43*C43
A44: 기타브랜드 | B44: [애니플렉스][ANIPLEX] 귀멸의 칼날 캔 케이스 스티커 세트 아카자 | C44: 24500 | D44: 0 | E44: =D44*C44 | F44: 1 | G44: =F44*C44
A45: 기타브랜드 | B45: [애니플렉스][ANIPLEX] 귀멸의 칼날 캔 케이스 스티커 세트 우즈이 텐겐 | C45: 24500 | D45: 0 | E45: =D45*C45 | F45: 1 | G45: =F45*C45
A46: 기타브랜드 | B46: [애니플렉스][ANIPLEX] 귀멸의 칼날 캔 케이스 스티커 세트 카마도 탄지로 | C46: 24500 | D46: 0 | E46: =D46*C46 | F46: 1 | G46: =F46*C46
A47: 기타브랜드 | B47: [애니플렉스][ANIPLEX] 귀멸의 칼날 캔 케이스 스티커 세트 코쿠시보 | C47: 24500 | D47: 0 | E47: =D47*C47 | F47: 1 | G47: =F47*C47
A48: 기타브랜드 | B48: [애니플렉스][ANIPLEX] 귀멸의 칼날 캔 케이스 스티커 세트 키부츠지 무잔 | C48: 24500 | D48: 0 | E48: =D48*C48 | F48: 1 | G48: =F48*C48
A49: 기타브랜드 | B49: [애니플렉스][ANIPLEX] 귀멸의 칼날 캔 케이스 스티커 세트 토미오카 기유 | C49: 24500 | D49: 0 | E49: =D49*C49 | F49: 1 | G49: =F49*C49
A50: 기타브랜드 | B50: [애니플렉스][ANIPLEX] 귀멸의 칼날 캔 케이스 스티커 세트 하시비라 이노스케 | C50: 24500 | D50: 0 | E50: =D50*C50 | F50: 1 | G50: =F50*C50
A51: 기타브랜드 | B51: [애니플렉스][ANIPLEX] 마법소녀 마도카☆마기카 아크릴 스탠드 미키 사야카 | C51: 14700 | D51: 0 | E51: =D51*C51 | F51: 1 | G51: =F51*C51
A52: 기타브랜드 | B52: [애니플렉스][ANIPLEX] 마법소녀 마도카☆마기카 아크릴 스탠드 사쿠라 쿄코 | C52: 14700 | D52: 0 | E52: =D52*C52 | F52: 1 | G52: =F52*C52
...
